Workbook

Sheet Summary
A1: Claim 20-2023-700 - Repair Estimate
A3: What happened:
A4: Drain line in laundry room backed up and water affected the laundry room, downstairs bathroom, hallway, office, and family room.
A5: Mold treatment completed. This estimate covers remaining repair and finish work only.
A6: Owner acting as general contractor. Subs: carpet install, shower system install, concrete leveling. All other work owner-performed. All pricing sourced and linked (see Pricing Sources tab).
A8: Room | B8: Dimensions | C8: Scope of Repair | D8: Room Total
A9: Office | B9: 11'7"x14'5" + offset + closet | C9: LifeProof carpet, concrete leveling, drywall, baseboard, texture, paint | D9: =Office!F51 -> 5826.88
A10: Laundry Room | B10: 14'7" x 11'7" | C10: LVP floor, walls, door/trim, baseboard, paint | D10: ='Laundry Room'!F48 -> 5315.51
A11: Downstairs Bathroom | B11: 6'9" x 7' | C11: DreamStone shower, tile surround, vanity, vinyl floor, door/trim, baseboard, paint | D11: ='Downstairs Bathroom'!F61 -> 9376.6
A12: Hallway | B12: 14' x 3'3" + offset | C12: LifeProof carpet, concrete leveling, drywall, baseboard, texture, paint | D12: =Hallway!F47 -> 2922.36
A13: Family Room | B13: 14' x 3'3" + offset | C13: LifeProof carpet, concrete leveling, drywall, paneling, baseboard, texture, paint | D13: ='Family Room'!F52 -> 3401.12
A14: GRAND TOTAL | D14: =SUM(D9:D13) -> 26842.47
A16: Legend:
A17: Yellow rows | B17: Owner-performed labor (valued at contractor rates)
A18: Blue rows | B18: Subcontractor labor
A19: Blue underlined costs | B19: Clickable link to pricing source

Sheet Office
A1: Claim 20-2023-700 - Office
A3: Room: | B3: Office
A4: Dimensions: | B4: 11'7" x 14'5" + offset 8x3'7" + closet 8x3'5"
A5: Areas of Repair: | B5: Full room: LifeProof carpet & pad, concrete crack repair & leveling, drywall repair, all baseboard replaced, texture & paint all walls
A7: Category | B7: Material / Item | C7: Qty | D7: Unit | E7: Unit Cost | F7: Extended Cost | G7: Notes
A8: Flooring | B8: LifeProof w/ Petproof Technology - low pile carpet | C8: 223 | D8: SF | E8: =HYPERLINK("https://www.homedepot.com/b/Flooring-Carpet/Lifeproof-with-Petproof-Technology/N-5yc1vZarl0Zs7d",5.49) -> 5.49 | F8: =C8*E8 -> 1224.27 | G8: Triexta, lifetime pet-stain warranty, 25yr wear
A9: Flooring | B9: LifeProof 1/2" Premium Comfort Foam pad (SpillSafe) | C9: 223 | D9: SF | E9: =HYPERLINK("https://www.homedepot.com/p/Lifeproof-1-2-in-Thick-Premium-Comfort-Foam-Carpet-Pad-with-Double-Sided-Waterproof-SpillSafe-Membrane-100502850-04/316061675",1.35) -> 1.35 | F9: =C9*E9 -> 301.05 | G9: Double-sided waterproof moisture barrier
A10: Flooring | B10: Tack strips | C10: 92 | D10: LF | E10: =HYPERLINK("https://www.homedepot.com/p/M-D-Building-Products-4-ft-Carpet-Tack-Strip-50-Pack-75093/202066639",0.45) -> 0.45 | F10: =C10*E10 -> 41.4 | G10: Full room perimeter
A11: Flooring | B11: Carpet seam tape | C11: 1 | D11: roll | E11: =HYPERLINK("https://www.homedepot.com/p/Roberts-3-in-x-164-ft-Hot-Melt-Seam-Tape-50-325/100147104",12.98) -> 12.98 | F11: =C11*E11 -> 12.98
A12: Concrete | B12: Epoxy crack filler (10oz cartridge) | C12: 3 | D12: ea | E12: =HYPERLINK("https://www.homedepot.com/p/DAP-Concrete-and-Mortar-Filler-and-Sealant-9-8-oz-Limestone-18096/202522393",9.98) -> 9.98 | F12: =C12*E12 -> 29.94 | G12: Phase 1: Individual crack repair
A13: Concrete | B13: Concrete crack backer rod (3/8") | C13: 1 | D13: roll | E13: =HYPERLINK("https://www.homedepot.com/p/M-D-Building-Products-3-8-in-x-20-ft-Caulk-Backer-Rod-71464/202066517",4.48) -> 4.48 | F13: =C13*E13 -> 4.48
A14: Concrete | B14: Concrete bonding adhesive | C14: 1 | D14: gal | E14: =HYPERLINK("https://www.homedepot.com/p/Quikrete-1-Qt-Concrete-Bonding-Adhesive-990201/100318507",9.98) -> 9.98 | F14: =C14*E14 -> 9.98
A15: Concrete | B15: Hydraulic cement (10 lb) | C15: 1 | D15: bag | E15: =HYPERLINK("https://www.homedepot.com/p/Quikrete-10-lb-Hydraulic-Water-Stop-Cement-112611/100318494",12.48) -> 12.48 | F15: =C15*E15 -> 12.48 | G15: Wider cracks / spalling
A16: Concrete | B16: Self-leveling compound (50 lb bag) | C16: 7 | D16: bag | E16: =HYPERLINK("https://www.homedepot.com/p/Henry-555-Level-Pro-40-lb-Self-Leveling-Underlayment-12165/100111942",36.97) -> 36.97 | F16: =C16*E16 -> 258.79 | G16: Phase 2 if needed: Full floor ~223 SF
A17: Concrete | B17: SLC primer / bonding agent (1 gal) | C17: 1 | D17: gal | E17: =HYPERLINK("https://www.homedepot.com/p/Henry-336-1-Gal-Floor-Primer-and-Underlayment-Additive-12195/100111940",27.98) -> 27.98 | F17: =C17*E17 -> 27.98 | G17: Required prep for SLC
A18: Drywall | B18: 1/2" x 4'x8' standard drywall | C18: 5 | D18: sheet | E18: =HYPERLINK("https://www.homedepot.com/p/USG-Sheetrock-Brand-1-2-in-x-4-ft-x-8-ft-UltraLight-Drywall-14113411708/202530243",11.98) -> 11.98 | F18: =C18*E18 -> 59.9
A19: Drywall | B19: Drywall screws 1-1/4" coarse (1 lb) | C19: 2 | D19: box | E19: =HYPERLINK("https://www.homedepot.com/p/Grip-Rite-6-x-1-1-4-in-Philips-Bugle-Head-Coarse-Thread-Sharp-Point-Drywall-Screws-1-lb-Pack-114CDWS1/100153837",8.47) -> 8.47 | F19: =C19*E19 -> 16.94
A20: Drywall | B20: Paper drywall tape (250 ft) | C20: 2 | D20: roll | E20: =HYPERLINK("https://www.homedepot.com/p/USG-Sheetrock-Brand-2-1-16-in-x-250-ft-Paper-Joint-Tape-382175/100321614",4.88) -> 4.88 | F20: =C20*E20 -> 9.76
A21: Drywall | B21: All-purpose joint compound (4.5 gal) | C21: 2 | D21: bucket | E21: =HYPERLINK("https://www.homedepot.com/p/USG-Sheetrock-Brand-4-5-Gal-All-Purpose-Pre-Mixed-Joint-Compound-380501/100321602",19.48) -> 19.48 | F21: =C21*E21 -> 38.96
A22: Drywall | B22: Lightweight finishing compound (4.5 gal) | C22: 1 | D22: bucket | E22: =HYPERLINK("https://www.homedepot.com/p/USG-Sheetrock-Brand-4-5-Gal-Plus-3-Lightweight-All-Purpose-Pre-Mixed-Joint-Compound-381466/100321604",20.98) -> 20.98 | F22: =C22*E22 -> 20.98
A23: Drywall | B23: Sanding sponge (med/fine) | C23: 3 | D23: ea | E23: =HYPERLINK("https://www.homedepot.com/p/3M-2-7-8-in-x-4-7-8-in-x-1-in-Fine-Medium-Drywall-Sanding-Sponge-9093DCNA/100353968",4.97) -> 4.97 | F23: =C23*E23 -> 14.91
A24: Trim | B24: Baseboard - 3-1/4" MDF primed (8ft) | C24: 12 | D24: piece | E24: =HYPERLINK("https://www.homedepot.com/p/Woodgrain-Millwork-623-1-2-in-x-3-1-4-in-x-96-in-Primed-MDF-Baseboard-Moulding-1-Piece-8-Total-Linear-Feet-10001007/203209370",8.98) -> 8.98 | F24: =C24*E24 -> 107.76 | G24: ~92 LF full perimeter
A25: Trim | B25: Inside/outside corner blocks | C25: 8 | D25: ea | E25: =HYPERLINK("https://www.homedepot.com/p/House-of-Fara-3-4-in-x-3-1-4-in-x-3-1-4-in-MDF-Primed-Plinth-Block-8621/205426918",3.98) -> 3.98 | F25: =C25*E25 -> 31.84
A26: Trim | B26: 18ga 2" brad nails (1000ct) | C26: 1 | D26: box | E26: =HYPERLINK("https://www.homedepot.com/p/Grip-Rite-2-in-18-Gauge-Brad-Nails-1000-Pack-GRF18200/202308594",7.98) -> 7.98 | F26: =C26*E26 -> 7.98
A27: Trim | B27: Paintable latex caulk | C27: 3 | D27: tube | E27: =HYPERLINK("https://www.homedepot.com/p/DAP-Alex-Plus-10-1-oz-White-Acrylic-Latex-Caulk-Plus-Silicone-18103/100097524",3.98) -> 3.98 | F27: =C27*E27 -> 11.94
A28: Trim | B28: Wood filler / spackle | C28: 1 | D28: tube | E28: =HYPERLINK("https://www.homedepot.com/p/DAP-Plastic-Wood-X-with-DryDex-5-5-oz-All-Purpose-Wood-Filler-00540/206667344",6.98) -> 6.98 | F28: =C28*E28 -> 6.98
A29: Texture | B29: Spray texture - orange peel/knockdown (25oz) | C29: 5 | D29: can | E29: =HYPERLINK("https://www.homedepot.com/p/Homax-20-oz-Wall-Orange-Peel-Low-Odor-Water-Based-Texture-Spray-Paint-4092-06/100154309",16.98) -> 16.98 | F29: =C29*E29 -> 84.9 | G29: Match existing
A30: Paint | B30: Zinsser Bulls Eye 1-2-3 Primer (1 gal) | C30: 2 | D30: gal | E30: =HYPERLINK("https://www.homedepot.com/p/Zinsser-Bulls-Eye-1-2-3-1-Gal-White-Water-Based-Interior-Exterior-Primer-and-Sealer-2001/100398391",28.98) -> 28.98 | F30: =C30*E30 -> 57.96 | G30: All walls
A31: Paint | B31: BEHR Marquee interior paint - eggshell (1 gal) | C31: 3 | D31: gal | E31: =HYPERLINK("https://www.homedepot.com/p/BEHR-MARQUEE-1-gal-Ultra-Pure-White-Eggshell-Enamel-Interior-Paint-Primer-245001/204747490",54.98) -> 54.98 | F31: =C31*E31 -> 164.94 | G31: All walls, 2 coats (~500 SF)
A32: Paint | B32: BEHR Marquee semi-gloss trim paint (1 qt) | C32: 1 | D32: qt | E32: =HYPERLINK("https://www.homedepot.com/p/BEHR-MARQUEE-1-qt-Ultra-Pure-White-Semi-Gloss-Enamel-Interior-Paint-Primer-345004/204747525",23.98) -> 23.98 | F32: =C32*E32 -> 23.98 | G32: Baseboard & trim
A33: Paint | B33: Paint roller covers 3/8" nap (3-pack) | C33: 2 | D33: pack | E33: =HYPERLINK("https://www.homedepot.com/p/Wooster-9-in-x-3-8-in-Pro-American-Contractor-High-Density-Knit-Roller-Cover-3-Pack-0-RC660-9/205625717",11.97) -> 11.97 | F33: =C33*E33 -> 23.94
A34: Paint | B34: Roller frame & extension pole | C34: 1 | D34: ea | E34: =HYPERLINK("https://www.homedepot.com/p/Wooster-9-in-Sherlock-Frame-with-Jumbo-Koter-Cage-and-4-ft-to-8-ft-Sherlock-Extension-Pole-0R0170000/300697399",16.98) -> 16.98 | F34: =C34*E34 -> 16.98
A35: Paint | B35: Paint tray & liners | C35: 1 | D35: set | E35: =HYPERLINK("https://www.homedepot.com/p/HDX-9-in-Paint-Tray-Set-3-Piece-HD-RM-333/205879558",9.97) -> 9.97 | F35: =C35*E35 -> 9.97
A36: Paint | B36: Angled sash brush 2.5" | C36: 2 | D36: ea | E36: =HYPERLINK("https://www.homedepot.com/p/Wooster-2-1-2-in-Pro-Nylon-Polyester-Angle-Sash-Brush-0H21170024/100168988",8.98) -> 8.98 | F36: =C36*E36 -> 17.96
A37: Paint | B37: Painters tape (1.88" x 60yd) | C37: 3 | D37: roll | E37: =HYPERLINK("https://www.homedepot.com/p/ScotchBlue-1-88-in-x-60-yds-Sharp-Lines-Multi-Surface-Painters-Tape-2090-48TC/305375312",7.98) -> 7.98 | F37: =C37*E37 -> 23.94
A38: Supplies | B38: Plastic sheeting / drop cloths | C38: 2 | D38: pack | E38: =HYPERLINK("https://www.homedepot.com/p/HDX-9-ft-x-12-ft-0-7-mil-Drop-Cloth-2-Pack-DCHD-07-2/202528629",6.98) -> 6.98 | F38: =C38*E38 -> 13.96
A39: Supplies | B39: Disposal / debris hauling | C39: 1 | D39: flat | E39: 75 | F39: =C39*E39 -> 75 | G39: Old materials removal
A40: >>> OWNER-PERFORMED LABOR (valued at contractor equivalent rates)
A41: Owner Labor | B41: Carpet & pad removal (old) | C41: 223 | D41: SF | E41: 0.85 | F41: =C41*E41 -> 189.55 | G41: See Pricing Sources tab
A42: Owner Labor | B42: Drywall - hang, tape, mud, sand (Level 4) | C42: 130 | D42: SF | E42: 2.75 | F42: =C42*E42 -> 357.5 | G42: See Pricing Sources tab
...

Sheet Laundry Room
A1: Claim 20-2023-700 - Laundry Room
A3: Room: | B3: Laundry Room
A4: Dimensions: | B4: 14'7" x 11'7"
A5: Areas of Repair: | B5: Full room: LVP floor, all walls finished, all baseboard replaced, door & trim, texture & paint all walls
A6: Work Completed: | B6: Mold treatment completed
A8: Category | B8: Material / Item | C8: Qty | D8: Unit | E8: Unit Cost | F8: Extended Cost | G8: Notes
A9: Flooring | B9: Luxury vinyl plank (waterproof, 5mm+ w/ pad) | C9: 169 | D9: SF | E9: =HYPERLINK("https://www.homedepot.com/p/Lifeproof-Trail-Oak-8-7-in-W-x-47-6-in-L-Luxury-Vinyl-Plank-Flooring-20-06-sq-ft-case-I96715L/300699284",3.79) -> 3.79 | F9: =C9*E9 -> 640.51
A10: Flooring | B10: LVP underlayment - 6mil poly moisture barrier | C10: 169 | D10: SF | E10: =HYPERLINK("https://www.homedepot.com/p/Roberts-6-mil-10-ft-x-25-ft-Polyethylene-Film-Vapor-Barrier-70-115/100564393",0.35) -> 0.35 | F10: =C10*E10 -> 59.15 | G10: Over concrete slab
A11: Flooring | B11: Transition strips (T-molding) | C11: 2 | D11: ea | E11: =HYPERLINK("https://www.homedepot.com/p/Zamma-Unfinished-Red-Oak-3-4-in-Thick-x-2-in-Wide-x-78-in-Length-Hardwood-T-Molding-01400502078/205721044",14.98) -> 14.98 | F11: =C11*E11 -> 29.96
A12: Flooring | B12: Quarter round / shoe molding (8ft) | C12: 7 | D12: piece | E12: =HYPERLINK("https://www.homedepot.com/p/Woodgrain-Millwork-WM-126-1-2-in-x-3-4-in-x-96-in-Primed-Finger-Jointed-Quarter-Round-Moulding-10001853/206082006",3.98) -> 3.98 | F12: =C12*E12 -> 27.86
A13: Drywall | B13: 1/2" x 4'x8' moisture-resistant drywall (green board) | C13: 10 | D13: sheet | E13: =HYPERLINK("https://www.homedepot.com/p/USG-Sheetrock-Brand-1-2-in-x-4-ft-x-8-ft-UltraLight-Mold-Tough-Drywall-14302111708/203768542",14.98) -> 14.98 | F13: =C13*E13 -> 149.8
A14: Drywall | B14: Drywall screws 1-1/4" coarse (1 lb) | C14: 3 | D14: box | E14: =HYPERLINK("https://www.homedepot.com/p/Grip-Rite-6-x-1-1-4-in-Philips-Bugle-Head-Coarse-Thread-Sharp-Point-Drywall-Screws-1-lb-Pack-114CDWS1/100153837",8.47) -> 8.47 | F14: =C14*E14 -> 25.41
A15: Drywall | B15: Paper drywall tape (250 ft) | C15: 3 | D15: roll | E15: =HYPERLINK("https://www.homedepot.com/p/USG-Sheetrock-Brand-2-1-16-in-x-250-ft-Paper-Joint-Tape-382175/100321614",4.88) -> 4.88 | F15: =C15*E15 -> 14.64
A16: Drywall | B16: All-purpose joint compound (4.5 gal) | C16: 3 | D16: bucket | E16: =HYPERLINK("https://www.homedepot.com/p/USG-Sheetrock-Brand-4-5-Gal-All-Purpose-Pre-Mixed-Joint-Compound-380501/100321602",19.48) -> 19.48 | F16: =C16*E16 -> 58.44
A17: Drywall | B17: Lightweight finishing compound (4.5 gal) | C17: 1 | D17: bucket | E17: =HYPERLINK("https://www.homedepot.com/p/USG-Sheetrock-Brand-4-5-Gal-Plus-3-Lightweight-All-Purpose-Pre-Mixed-Joint-Compound-381466/100321604",20.98) -> 20.98 | F17: =C17*E17 -> 20.98
A18: Drywall | B18: Sanding sponge (med/fine) | C18: 3 | D18: ea | E18: =HYPERLINK("https://www.homedepot.com/p/3M-2-7-8-in-x-4-7-8-in-x-1-in-Fine-Medium-Drywall-Sanding-Sponge-9093DCNA/100353968",4.97) -> 4.97 | F18: =C18*E18 -> 14.91
A19: Door/Trim | B19: Interior prehung door - solid core (32") | C19: 1 | D19: ea | E19: =HYPERLINK("https://www.homedepot.com/p/Masonite-32-in-x-80-in-Lincoln-Park-Primed-1-Panel-Solid-Core-Composite-Interior-Door-Slab-10555/204418170",218) -> 218 | F19: =C19*E19 -> 218
A20: Door/Trim | B20: Door casing set - colonial (3-piece) | C20: 1 | D20: set | E20: =HYPERLINK("https://www.homedepot.com/p/Alexandria-Moulding-2-3-4-in-x-6-7-8-in-x-84-in-Primed-MDF-Door-Casing-Kit-02004-93084C/309671432",42.98) -> 42.98 | F20: =C20*E20 -> 42.98
A21: Door/Trim | B21: Door hardware - lever handle | C21: 1 | D21: ea | E21: =HYPERLINK("https://www.homedepot.com/p/Kwikset-Juno-Satin-Nickel-Passage-Hall-Closet-Door-Knob-720J-15-6AL-RCS/100689825",29.98) -> 29.98 | F21: =C21*E21 -> 29.98
A22: Door/Trim | B22: Door hinges (3-pack, satin nickel) | C22: 1 | D22: pack | E22: =HYPERLINK("https://www.homedepot.com/p/Everbilt-3-1-2-in-Satin-Nickel-5-8-in-Radius-Security-Door-Hinges-Value-Pack-3-Pack-14810/202818897",13.47) -> 13.47 | F22: =C22*E22 -> 13.47
A23: Door/Trim | B23: Door stop + shims | C23: 1 | D23: ea | E23: =HYPERLINK("https://www.homedepot.com/p/Everbilt-Rigid-Door-Stop-in-Satin-Nickel-15578/202033984",4.98) -> 4.98 | F23: =C23*E23 -> 4.98
A24: Trim | B24: Baseboard - 3-1/4" MDF primed (8ft) | C24: 7 | D24: piece | E24: =HYPERLINK("https://www.homedepot.com/p/Woodgrain-Millwork-623-1-2-in-x-3-1-4-in-x-96-in-Primed-MDF-Baseboard-Moulding-1-Piece-8-Total-Linear-Feet-10001007/203209370",8.98) -> 8.98 | F24: =C24*E24 -> 62.86 | G24: ~49 LF full perimeter
A25: Trim | B25: Inside/outside corner blocks | C25: 6 | D25: ea | E25: =HYPERLINK("https://www.homedepot.com/p/House-of-Fara-3-4-in-x-3-1-4-in-x-3-1-4-in-MDF-Primed-Plinth-Block-8621/205426918",3.98) -> 3.98 | F25: =C25*E25 -> 23.88
A26: Trim | B26: 18ga 2" brad nails (1000ct) | C26: 1 | D26: box | E26: =HYPERLINK("https://www.homedepot.com/p/Grip-Rite-2-in-18-Gauge-Brad-Nails-1000-Pack-GRF18200/202308594",7.98) -> 7.98 | F26: =C26*E26 -> 7.98
A27: Trim | B27: Paintable latex caulk | C27: 2 | D27: tube | E27: =HYPERLINK("https://www.homedepot.com/p/DAP-Alex-Plus-10-1-oz-White-Acrylic-Latex-Caulk-Plus-Silicone-18103/100097524",3.98) -> 3.98 | F27: =C27*E27 -> 7.96
A28: Trim | B28: Wood filler / spackle | C28: 1 | D28: tube | E28: =HYPERLINK("https://www.homedepot.com/p/DAP-Plastic-Wood-X-with-DryDex-5-5-oz-All-Purpose-Wood-Filler-00540/206667344",6.98) -> 6.98 | F28: =C28*E28 -> 6.98
A29: Texture | B29: Spray texture - orange peel/knockdown (25oz) | C29: 5 | D29: can | E29: =HYPERLINK("https://www.homedepot.com/p/Homax-20-oz-Wall-Orange-Peel-Low-Odor-Water-Based-Texture-Spray-Paint-4092-06/100154309",16.98) -> 16.98 | F29: =C29*E29 -> 84.9 | G29: Match existing
A30: Paint | B30: Zinsser Mold Killing Primer (1 gal) | C30: 2 | D30: gal | E30: =HYPERLINK("https://www.homedepot.com/p/Zinsser-Mold-Killing-1-Gal-White-Water-Based-Interior-Exterior-Primer-276049/202520508",28.98) -> 28.98 | F30: =C30*E30 -> 57.96 | G30: All walls
A31: Paint | B31: BEHR Marquee interior paint - eggshell (1 gal) | C31: 2 | D31: gal | E31: =HYPERLINK("https://www.homedepot.com/p/BEHR-MARQUEE-1-gal-Ultra-Pure-White-Eggshell-Enamel-Interior-Paint-Primer-245001/204747490",54.98) -> 54.98 | F31: =C31*E31 -> 109.96 | G31: All walls, 2 coats (~420 SF)
A32: Paint | B32: BEHR Marquee semi-gloss trim paint (1 qt) | C32: 1 | D32: qt | E32: =HYPERLINK("https://www.homedepot.com/p/BEHR-MARQUEE-1-qt-Ultra-Pure-White-Semi-Gloss-Enamel-Interior-Paint-Primer-345004/204747525",23.98) -> 23.98 | F32: =C32*E32 -> 23.98 | G32: Baseboard & trim
A33: Paint | B33: Paint roller covers 3/8" nap (3-pack) | C33: 2 | D33: pack | E33: =HYPERLINK("https://www.homedepot.com/p/Wooster-9-in-x-3-8-in-Pro-American-Contractor-High-Density-Knit-Roller-Cover-3-Pack-0-RC660-9/205625717",11.97) -> 11.97 | F33: =C33*E33 -> 23.94
A34: Paint | B34: Roller frame & extension pole | C34: 1 | D34: ea | E34: =HYPERLINK("https://www.homedepot.com/p/Wooster-9-in-Sherlock-Frame-with-Jumbo-Koter-Cage-and-4-ft-to-8-ft-Sherlock-Extension-Pole-0R0170000/300697399",16.98) -> 16.98 | F34: =C34*E34 -> 16.98
A35: Paint | B35: Paint tray & liners | C35: 1 | D35: set | E35: =HYPERLINK("https://www.homedepot.com/p/HDX-9-in-Paint-Tray-Set-3-Piece-HD-RM-333/205879558",9.97) -> 9.97 | F35: =C35*E35 -> 9.97
A36: Paint | B36: Angled sash brush 2.5" | C36: 2 | D36: ea | E36: =HYPERLINK("https://www.homedepot.com/p/Wooster-2-1-2-in-Pro-Nylon-Polyester-Angle-Sash-Brush-0H21170024/100168988",8.98) -> 8.98 | F36: =C36*E36 -> 17.96
A37: Paint | B37: Painters tape (1.88" x 60yd) | C37: 3 | D37: roll | E37: =HYPERLINK("https://www.homedepot.com/p/ScotchBlue-1-88-in-x-60-yds-Sharp-Lines-Multi-Surface-Painters-Tape-2090-48TC/305375312",7.98) -> 7.98 | F37: =C37*E37 -> 23.94
A38: Paint | B38: Paint supplies (rollers, brushes, tape, tray) | C38: 1 | D38: kit | E38: =HYPERLINK("https://www.homedepot.com/p/Wooster-9-in-Sherlock-Frame-with-Jumbo-Koter-Cage-and-4-ft-to-8-ft-Sherlock-Extension-Pole-0R0170000/300697399",39.98) -> 39.98 | F38: =C38*E38 -> 39.98
A39: Supplies | B39: Plastic sheeting / drop cloths | C39: 2 | D39: pack | E39: =HYPERLINK("https://www.homedepot.com/p/HDX-9-ft-x-12-ft-0-7-mil-Drop-Cloth-2-Pack-DCHD-07-2/202528629",6.98) -> 6.98 | F39: =C39*E39 -> 13.96
A40: Supplies | B40: Disposal / debris hauling | C40: 1 | D40: flat | E40: 100 | F40: =C40*E40 -> 100 | G40: Old materials removal
A41: >>> OWNER-PERFORMED LABOR (valued at contractor equivalent rates)
A42: Owner Labor | B42: LVP flooring installation | C42: 169 | D42: SF | E42: 3 | F42: =C42*E42 -> 507 | G42: Incl subfloor prep, underlayment
...

Sheet Downstairs Bathroom
A1: Claim 20-2023-700 - Downstairs Bathroom
A3: Room: | B3: Downstairs Bathroom
A4: Dimensions: | B4: 6'9" x 7'
A5: Areas of Repair: | B5: Full room: DreamLine shower system (2'7"x4'1"), tile surround (4ft high), vanity & sink hookup (3'x1'8"), vinyl floor, door & trim, skim coat, all baseboard, all walls painted
A6: Work Completed: | B6: Demo done, wet material removed, mold treated, drywall replaced
A8: Category | B8: Material / Item | C8: Qty | D8: Unit | E8: Unit Cost | F8: Extended Cost | G8: Notes
A9: Flooring | B9: Luxury vinyl plank/tile (waterproof, bathroom) | C9: 47 | D9: SF | E9: =HYPERLINK("https://www.homedepot.com/p/Lifeproof-Trail-Oak-8-7-in-W-x-47-6-in-L-Luxury-Vinyl-Plank-Flooring-20-06-sq-ft-case-I96715L/300699284",3.79) -> 3.79 | F9: =C9*E9 -> 178.13
A10: Flooring | B10: Vinyl adhesive / underlayment | C10: 47 | D10: SF | E10: =HYPERLINK("https://www.homedepot.com/p/Roberts-6-mil-10-ft-x-25-ft-Polyethylene-Film-Vapor-Barrier-70-115/100564393",0.35) -> 0.35 | F10: =C10*E10 -> 16.45
A11: Flooring | B11: Transition strip | C11: 1 | D11: ea | E11: =HYPERLINK("https://www.homedepot.com/p/Zamma-Unfinished-Red-Oak-3-4-in-Thick-x-2-in-Wide-x-78-in-Length-Hardwood-T-Molding-01400502078/205721044",14.98) -> 14.98 | F11: =C11*E11 -> 14.98
A12: Shower System | B12: DreamLine DreamStone alcove kit (34"x54"x84" base + walls, Modern White) | C12: 1 | D12: ea | E12: =HYPERLINK("https://www.homedepot.com/p/DreamLine-DreamStone-34-in-L-x-54-in-W-x-84-in-H-Alcove-Shower-Kit-with-Shower-Wall-and-Shower-Pan-in-Modern-White-BWDS54341MC0001/319836218",3149.18) -> 3149.18 | F12: =C12*E12 -> 3149.18 | G12: Premium solid surface, mold/chip/crack resistant, slip-resistant. Door separate if needed.
A13: Shower System | B13: Shower trim kit (showerhead, handle, flange) | C13: 1 | D13: set | E13: =HYPERLINK("https://www.homedepot.com/p/MOEN-Adler-Single-Handle-1-Spray-Tub-and-Shower-Faucet-in-Brushed-Nickel-Valve-Included-82604SRN/312295481",109) -> 109 | F13: =C13*E13 -> 109 | G13: Coordinated brushed nickel
A14: Shower System | B14: Shower arm & flange | C14: 1 | D14: ea | E14: =HYPERLINK("https://www.homedepot.com/p/Glacier-Bay-10-in-Wall-Mount-Shower-Arm-in-Brushed-Nickel-3075-554/305238221",19.98) -> 19.98 | F14: =C14*E14 -> 19.98
A15: Shower System | B15: Silicone caulk - bath (clear + white) | C15: 3 | D15: tube | E15: =HYPERLINK("https://www.homedepot.com/p/DAP-Kwik-Seal-Plus-10-1-oz-White-Kitchen-and-Bath-Adhesive-Caulk-18510/100634364",5.98) -> 5.98 | F15: =C15*E15 -> 17.94 | G15: System seams & perimeter
A16: Shower System | B16: Panel adhesive (per DreamLine specs) | C16: 2 | D16: tube | E16: =HYPERLINK("https://www.homedepot.com/p/Loctite-Power-Grab-Express-9-fl-oz-All-Purpose-Construction-Adhesive-2029846/206736498",7.98) -> 7.98 | F16: =C16*E16 -> 15.96
A17: Tile | B17: Porcelain wall tile - surround (4ft high, excl shower) | C17: 98 | D17: SF | E17: =HYPERLINK("https://www.homedepot.com/p/Daltile-Restore-Bright-White-3-in-x-6-in-Ceramic-Modular-Wall-Tile-12-5-sq-ft-case-RE15836MODHD1P2/307562453",5.98) -> 5.98 | F17: =C17*E17 -> 586.04 | G17: ~24.5 LF x 4ft
A18: Tile | B18: Bullnose / edge trim tile | C18: 28 | D18: LF | E18: =HYPERLINK("https://www.homedepot.com/p/Daltile-Restore-Bright-White-2-in-x-6-in-Ceramic-Bullnose-Wall-Tile-0-08-sq-ft-Piece-RE15826BN1P2/307562448",2.98) -> 2.98 | F18: =C18*E18 -> 83.44 | G18: Top edge of surround
A19: Tile | B19: Cement backer board (3'x5') | C19: 5 | D19: sheet | E19: =HYPERLINK("https://www.homedepot.com/p/James-Hardie-HardieBacker-0-42-in-x-3-ft-x-5-ft-Cement-Backerboard-220023/100170507",14.68) -> 14.68 | F19: =C19*E19 -> 73.4 | G19: Substrate for surround
A20: Tile | B20: Backer board screws + alkali-resistant tape | C20: 1 | D20: kit | E20: =HYPERLINK("https://www.homedepot.com/p/Grip-Rite-1-5-8-in-Cement-Board-Screw-1-lb-Box-158CEMBR1/205690610",12.98) -> 12.98 | F20: =C20*E20 -> 12.98
A21: Tile | B21: Modified thinset mortar (50 lb) | C21: 3 | D21: bag | E21: =HYPERLINK("https://www.homedepot.com/p/Custom-Building-Products-VersaBond-50-lb-White-Professional-Polymer-Modified-Thinset-Mortar-MTSW50/100091767",21.98) -> 21.98 | F21: =C21*E21 -> 65.94
A22: Tile | B22: Unsanded grout (10 lb) | C22: 2 | D22: bag | E22: =HYPERLINK("https://www.homedepot.com/p/Custom-Building-Products-Polyblend-Plus-10-lb-Bright-White-Non-Sanded-Grout-PBPG38110/308958095",16.98) -> 16.98 | F22: =C22*E22 -> 33.96
A23: Tile | B23: Grout sealer | C23: 1 | D23: bottle | E23: =HYPERLINK("https://www.homedepot.com/p/Custom-Building-Products-TileLab-22-oz-Grout-and-Tile-Sealer-Spray-TLPSRA22Z/206410048",13.98) -> 13.98 | F23: =C23*E23 -> 13.98
A24: Tile | B24: Tile spacers, leveling system | C24: 1 | D24: kit | E24: =HYPERLINK("https://www.homedepot.com/p/QEP-LASH-Tile-Leveling-Aligning-and-Spacer-Clips-Part-A-and-B-100-Pack-99720/300648014",24.98) -> 24.98 | F24: =C24*E24 -> 24.98
A25: Tile | B25: Silicone caulk - tile corners/transitions | C25: 2 | D25: tube | E25: =HYPERLINK("https://www.homedepot.com/p/DAP-Kwik-Seal-Plus-10-1-oz-White-Kitchen-and-Bath-Adhesive-Caulk-18510/100634364",5.98) -> 5.98 | F25: =C25*E25 -> 11.96
A26: Vanity/Sink | B26: Bathroom vanity w/ solid surface top (30"-36") | C26: 1 | D26: ea | E26: =HYPERLINK("https://www.homedepot.com/p/Home-Decorators-Collection-Doveton-30-in-Single-Sink-Freestanding-White-Bath-Vanity-with-White-Engineered-Marble-Top-Quik-Set-DV3022-WH/326375001",549) -> 549 | F26: =C26*E26 -> 549 | G26: Mid-upper grade, soft-close
A27: Vanity/Sink | B27: Moen Genta bathroom faucet (brushed nickel) | C27: 1 | D27: ea | E27: =HYPERLINK("https://www.homedepot.com/p/MOEN-Genta-Single-Handle-Single-Hole-Bathroom-Faucet-in-Brushed-Nickel-WS84760SRN/301980213",109) -> 109 | F27: =C27*E27 -> 109
A28: Vanity/Sink | B28: Drain assembly & pop-up | C28: 1 | D28: ea | E28: =HYPERLINK("https://www.homedepot.com/p/Everbilt-Bathroom-Pop-Up-Drain-Assembly-in-Brushed-Nickel-20390/204608142",14.98) -> 14.98 | F28: =C28*E28 -> 14.98
A29: Vanity/Sink | B29: P-trap assembly | C29: 1 | D29: ea | E29: =HYPERLINK("https://www.homedepot.com/p/Everbilt-1-1-4-in-White-Plastic-Sink-Drain-P-Trap-with-Reversible-J-Bend-C9704B/205153738",7.98) -> 7.98 | F29: =C29*E29 -> 7.98
A30: Vanity/Sink | B30: Supply lines - braided stainless (2) | C30: 2 | D30: ea | E30: =HYPERLINK("https://www.homedepot.com/p/BrassCraft-3-8-in-Comp-x-1-2-in-FIP-x-20-in-Braided-Stainless-Steel-Faucet-Connector-B1-20A-F/100464003",9.98) -> 9.98 | F30: =C30*E30 -> 19.96
A31: Vanity/Sink | B31: Plumbers putty / teflon tape | C31: 1 | D31: ea | E31: =HYPERLINK("https://www.homedepot.com/p/Oatey-14-oz-Stain-Free-Plumbers-Putty-254873/100345636",5.97) -> 5.97 | F31: =C31*E31 -> 5.97
A32: Vanity/Sink | B32: Framed mirror (wall mount) | C32: 1 | D32: ea | E32: =HYPERLINK("https://www.homedepot.com/p/Home-Decorators-Collection-Medium-Rectangle-Black-Modern-Mirror-27-5-in-H-x-21-5-in-W-L7-MH-7421/316078218",89.98) -> 89.98 | F32: =C32*E32 -> 89.98
A33: Door/Trim | B33: Interior prehung door - solid core (28"-30") | C33: 1 | D33: ea | E33: =HYPERLINK("https://www.homedepot.com/p/Masonite-30-in-x-80-in-Lincoln-Park-Primed-1-Panel-Solid-Core-Composite-Interior-Door-Slab-10556/205746638",208) -> 208 | F33: =C33*E33 -> 208
A34: Door/Trim | B34: Door casing set - colonial | C34: 1 | D34: set | E34: =HYPERLINK("https://www.homedepot.com/p/Alexandria-Moulding-2-3-4-in-x-6-7-8-in-x-84-in-Primed-MDF-Door-Casing-Kit-02004-93084C/309671432",42.98) -> 42.98 | F34: =C34*E34 -> 42.98
A35: Door/Trim | B35: Door hardware - privacy lever (brushed nickel) | C35: 1 | D35: ea | E35: =HYPERLINK("https://www.homedepot.com/p/Kwikset-Juno-Satin-Nickel-Privacy-Bed-Bath-Door-Knob-730J-15-6AL-RCS/100689824",34.98) -> 34.98 | F35: =C35*E35 -> 34.98
A36: Door/Trim | B36: Door hinges (satin nickel) | C36: 1 | D36: pack | E36: =HYPERLINK("https://www.homedepot.com/p/Everbilt-3-1-2-in-Satin-Nickel-5-8-in-Radius-Security-Door-Hinges-Value-Pack-3-Pack-14810/202818897",13.47) -> 13.47 | F36: =C36*E36 -> 13.47
A37: Trim | B37: Baseboard - 3-1/4" MDF primed (8ft) | C37: 4 | D37: piece | E37: =HYPERLINK("https://www.homedepot.com/p/Woodgrain-Millwork-623-1-2-in-x-3-1-4-in-x-96-in-Primed-MDF-Baseboard-Moulding-1-Piece-8-Total-Linear-Feet-10001007/203209370",8.98) -> 8.98 | F37: =C37*E37 -> 35.92 | G37: ~28 LF full perimeter
A38: Trim | B38: Inside/outside corner blocks | C38: 4 | D38: ea | E38: =HYPERLINK("https://www.homedepot.com/p/House-of-Fara-3-4-in-x-3-1-4-in-x-3-1-4-in-MDF-Primed-Plinth-Block-8621/205426918",3.98) -> 3.98 | F38: =C38*E38 -> 15.92
A39: Trim | B39: 18ga 2" brad nails (1000ct) | C39: 1 | D39: box | E39: =HYPERLINK("https://www.homedepot.com/p/Grip-Rite-2-in-18-Gauge-Brad-Nails-1000-Pack-GRF18200/202308594",7.98) -> 7.98 | F39: =C39*E39 -> 7.98
A40: Trim | B40: Paintable latex caulk | C40: 2 | D40: tube | E40: =HYPERLINK("https://www.homedepot.com/p/DAP-Alex-Plus-10-1-oz-White-Acrylic-Latex-Caulk-Plus-Silicone-18103/100097524",3.98) -> 3.98 | F40: =C40*E40 -> 7.96
A41: Trim | B41: Wood filler / spackle | C41: 1 | D41: tube | E41: =HYPERLINK("https://www.homedepot.com/p/DAP-Plastic-Wood-X-with-DryDex-5-5-oz-All-Purpose-Wood-Filler-00540/206667344",6.98) -> 6.98 | F41: =C41*E41 -> 6.98
A42: Drywall | B42: Joint compound - skim coat (4.5 gal) | C42: 1 | D42: bucket | E42: =HYPERLINK("https://www.homedepot.com/p/USG-Sheetrock-Brand-4-5-Gal-All-Purpose-Pre-Mixed-Joint-Compound-380501/100321602",19.48) -> 19.48 | F42: =C42*E42 -> 19.48
...

Sheet Hallway
A1: Claim 20-2023-700 - Hallway
A3: Room: | B3: Hallway
A4: Dimensions: | B4: 14' x 3'3" + offset 3'1" x 4'10"
A5: Areas of Repair: | B5: Full area: LifeProof carpet & pad, concrete crack repair & leveling, drywall, all baseboard, texture, paint all walls
A6: Work Completed: | B6: Floor demo, wet material removed, mold treatment completed
A8: Category | B8: Material / Item | C8: Qty | D8: Unit | E8: Unit Cost | F8: Extended Cost | G8: Notes
A9: Flooring | B9: LifeProof w/ Petproof Technology - low pile carpet | C9: 61 | D9: SF | E9: =HYPERLINK("https://www.homedepot.com/b/Flooring-Carpet/Lifeproof-with-Petproof-Technology/N-5yc1vZarl0Zs7d",5.49) -> 5.49 | F9: =C9*E9 -> 334.89 | G9: Triexta, lifetime pet-stain warranty, 25yr wear
A10: Flooring | B10: LifeProof 1/2" Premium Comfort Foam pad (SpillSafe) | C10: 61 | D10: SF | E10: =HYPERLINK("https://www.homedepot.com/p/Lifeproof-1-2-in-Thick-Premium-Comfort-Foam-Carpet-Pad-with-Double-Sided-Waterproof-SpillSafe-Membrane-100502850-04/316061675",1.35) -> 1.35 | F10: =C10*E10 -> 82.35 | G10: Double-sided waterproof moisture barrier
A11: Flooring | B11: Tack strips | C11: 42 | D11: LF | E11: =HYPERLINK("https://www.homedepot.com/p/M-D-Building-Products-4-ft-Carpet-Tack-Strip-50-Pack-75093/202066639",0.45) -> 0.45 | F11: =C11*E11 -> 18.9 | G11: Full room perimeter
A12: Flooring | B12: Carpet seam tape | C12: 1 | D12: roll | E12: =HYPERLINK("https://www.homedepot.com/p/Roberts-3-in-x-164-ft-Hot-Melt-Seam-Tape-50-325/100147104",12.98) -> 12.98 | F12: =C12*E12 -> 12.98
A13: Concrete | B13: Epoxy crack filler (10oz cartridge) | C13: 2 | D13: ea | E13: =HYPERLINK("https://www.homedepot.com/p/DAP-Concrete-and-Mortar-Filler-and-Sealant-9-8-oz-Limestone-18096/202522393",9.98) -> 9.98 | F13: =C13*E13 -> 19.96 | G13: Phase 1: Individual crack repair
A14: Concrete | B14: Concrete crack backer rod (3/8") | C14: 1 | D14: roll | E14: =HYPERLINK("https://www.homedepot.com/p/M-D-Building-Products-3-8-in-x-20-ft-Caulk-Backer-Rod-71464/202066517",4.48) -> 4.48 | F14: =C14*E14 -> 4.48
A15: Concrete | B15: Concrete bonding adhesive | C15: 1 | D15: gal | E15: =HYPERLINK("https://www.homedepot.com/p/Quikrete-1-Qt-Concrete-Bonding-Adhesive-990201/100318507",9.98) -> 9.98 | F15: =C15*E15 -> 9.98
A16: Concrete | B16: Hydraulic cement (10 lb) | C16: 1 | D16: bag | E16: =HYPERLINK("https://www.homedepot.com/p/Quikrete-10-lb-Hydraulic-Water-Stop-Cement-112611/100318494",12.48) -> 12.48 | F16: =C16*E16 -> 12.48 | G16: Wider cracks / spalling
A17: Concrete | B17: Self-leveling compound (50 lb bag) | C17: 3 | D17: bag | E17: =HYPERLINK("https://www.homedepot.com/p/Henry-555-Level-Pro-40-lb-Self-Leveling-Underlayment-12165/100111942",36.97) -> 36.97 | F17: =C17*E17 -> 110.91 | G17: Phase 2 if needed: Full floor ~61 SF
A18: Concrete | B18: SLC primer / bonding agent (1 gal) | C18: 1 | D18: gal | E18: =HYPERLINK("https://www.homedepot.com/p/Henry-336-1-Gal-Floor-Primer-and-Underlayment-Additive-12195/100111940",27.98) -> 27.98 | F18: =C18*E18 -> 27.98 | G18: Required prep for SLC
A19: Drywall | B19: 1/2" x 4'x8' standard drywall | C19: 4 | D19: sheet | E19: =HYPERLINK("https://www.homedepot.com/p/USG-Sheetrock-Brand-1-2-in-x-4-ft-x-8-ft-UltraLight-Drywall-14113411708/202530243",11.98) -> 11.98 | F19: =C19*E19 -> 47.92
A20: Drywall | B20: Drywall screws 1-1/4" coarse (1 lb) | C20: 2 | D20: box | E20: =HYPERLINK("https://www.homedepot.com/p/Grip-Rite-6-x-1-1-4-in-Philips-Bugle-Head-Coarse-Thread-Sharp-Point-Drywall-Screws-1-lb-Pack-114CDWS1/100153837",8.47) -> 8.47 | F20: =C20*E20 -> 16.94
A21: Drywall | B21: Paper drywall tape (250 ft) | C21: 1 | D21: roll | E21: =HYPERLINK("https://www.homedepot.com/p/USG-Sheetrock-Brand-2-1-16-in-x-250-ft-Paper-Joint-Tape-382175/100321614",4.88) -> 4.88 | F21: =C21*E21 -> 4.88
A22: Drywall | B22: All-purpose joint compound (4.5 gal) | C22: 1 | D22: bucket | E22: =HYPERLINK("https://www.homedepot.com/p/USG-Sheetrock-Brand-4-5-Gal-All-Purpose-Pre-Mixed-Joint-Compound-380501/100321602",19.48) -> 19.48 | F22: =C22*E22 -> 19.48
A23: Drywall | B23: Lightweight finishing compound (4.5 gal) | C23: 1 | D23: bucket | E23: =HYPERLINK("https://www.homedepot.com/p/USG-Sheetrock-Brand-4-5-Gal-Plus-3-Lightweight-All-Purpose-Pre-Mixed-Joint-Compound-381466/100321604",20.98) -> 20.98 | F23: =C23*E23 -> 20.98
A24: Drywall | B24: Sanding sponge (med/fine) | C24: 3 | D24: ea | E24: =HYPERLINK("https://www.homedepot.com/p/3M-2-7-8-in-x-4-7-8-in-x-1-in-Fine-Medium-Drywall-Sanding-Sponge-9093DCNA/100353968",4.97) -> 4.97 | F24: =C24*E24 -> 14.91
A25: Trim | B25: Baseboard - 3-1/4" MDF primed (8ft) | C25: 6 | D25: piece | E25: =HYPERLINK("https://www.homedepot.com/p/Woodgrain-Millwork-623-1-2-in-x-3-1-4-in-x-96-in-Primed-MDF-Baseboard-Moulding-1-Piece-8-Total-Linear-Feet-10001007/203209370",8.98) -> 8.98 | F25: =C25*E25 -> 53.88 | G25: ~42 LF full perimeter
A26: Trim | B26: Inside/outside corner blocks | C26: 6 | D26: ea | E26: =HYPERLINK("https://www.homedepot.com/p/House-of-Fara-3-4-in-x-3-1-4-in-x-3-1-4-in-MDF-Primed-Plinth-Block-8621/205426918",3.98) -> 3.98 | F26: =C26*E26 -> 23.88
A27: Trim | B27: 18ga 2" brad nails (1000ct) | C27: 1 | D27: box | E27: =HYPERLINK("https://www.homedepot.com/p/Grip-Rite-2-in-18-Gauge-Brad-Nails-1000-Pack-GRF18200/202308594",7.98) -> 7.98 | F27: =C27*E27 -> 7.98
A28: Trim | B28: Paintable latex caulk | C28: 2 | D28: tube | E28: =HYPERLINK("https://www.homedepot.com/p/DAP-Alex-Plus-10-1-oz-White-Acrylic-Latex-Caulk-Plus-Silicone-18103/100097524",3.98) -> 3.98 | F28: =C28*E28 -> 7.96
A29: Trim | B29: Wood filler / spackle | C29: 1 | D29: tube | E29: =HYPERLINK("https://www.homedepot.com/p/DAP-Plastic-Wood-X-with-DryDex-5-5-oz-All-Purpose-Wood-Filler-00540/206667344",6.98) -> 6.98 | F29: =C29*E29 -> 6.98
A30: Texture | B30: Spray texture - orange peel/knockdown (25oz) | C30: 3 | D30: can | E30: =HYPERLINK("https://www.homedepot.com/p/Homax-20-oz-Wall-Orange-Peel-Low-Odor-Water-Based-Texture-Spray-Paint-4092-06/100154309",16.98) -> 16.98 | F30: =C30*E30 -> 50.94 | G30: Match existing
A31: Paint | B31: Zinsser Bulls Eye 1-2-3 Primer (1 gal) | C31: 1 | D31: gal | E31: =HYPERLINK("https://www.homedepot.com/p/Zinsser-Bulls-Eye-1-2-3-1-Gal-White-Water-Based-Interior-Exterior-Primer-and-Sealer-2001/100398391",28.98) -> 28.98 | F31: =C31*E31 -> 28.98
A32: Paint | B32: BEHR Marquee interior paint - eggshell (1 gal) | C32: 2 | D32: gal | E32: =HYPERLINK("https://www.homedepot.com/p/BEHR-MARQUEE-1-gal-Ultra-Pure-White-Eggshell-Enamel-Interior-Paint-Primer-245001/204747490",54.98) -> 54.98 | F32: =C32*E32 -> 109.96 | G32: All walls, 2 coats
A33: Paint | B33: BEHR Marquee semi-gloss trim paint (1 qt) | C33: 1 | D33: qt | E33: =HYPERLINK("https://www.homedepot.com/p/BEHR-MARQUEE-1-qt-Ultra-Pure-White-Semi-Gloss-Enamel-Interior-Paint-Primer-345004/204747525",23.98) -> 23.98 | F33: =C33*E33 -> 23.98
A34: Paint | B34: Paint supplies (rollers, brush, tape) | C34: 1 | D34: kit | E34: =HYPERLINK("https://www.homedepot.com/p/Wooster-9-in-x-3-8-in-Pro-American-Contractor-High-Density-Knit-Roller-Cover-3-Pack-0-RC660-9/205625717",11.97) -> 11.97 | F34: =C34*E34 -> 11.97
A35: Supplies | B35: Plastic sheeting / drop cloths | C35: 1 | D35: pack | E35: =HYPERLINK("https://www.homedepot.com/p/HDX-9-ft-x-12-ft-0-7-mil-Drop-Cloth-2-Pack-DCHD-07-2/202528629",6.98) -> 6.98 | F35: =C35*E35 -> 6.98
A36: Supplies | B36: Disposal / debris hauling | C36: 1 | D36: flat | E36: 60 | F36: =C36*E36 -> 60 | G36: Old materials removal
A37: >>> OWNER-PERFORMED LABOR (valued at contractor equivalent rates)
A38: Owner Labor | B38: Carpet & pad removal (old) | C38: 61 | D38: SF | E38: 0.85 | F38: =C38*E38 -> 51.85 | G38: See Pricing Sources tab
A39: Owner Labor | B39: Drywall - hang, tape, mud, sand | C39: 100 | D39: SF | E39: 2.75 | F39: =C39*E39 -> 275 | G39: See Pricing Sources tab
A40: Owner Labor | B40: Texture application | C40: 100 | D40: SF | E40: 1.5 | F40: =C40*E40 -> 150 | G40: See Pricing Sources tab
A41: Owner Labor | B41: Baseboard removal & installation | C41: 42 | D41: LF | E41: 8.25 | F41: =C41*E41 -> 346.5 | G41: See Pricing Sources tab
A42: Owner Labor | B42: Paint - all walls + trim | C42: 280 | D42: SF | E42: 1.75 | F42: =C42*E42 -> 490 | G42: See Pricing Sources tab
...

Sheet Family Room
A1: Claim 20-2023-700 - Family Room
A3: Room: | B3: Family Room
A4: Dimensions: | B4: 14' x 3'3" + offset 3'1" x 4'10"
A5: Areas of Repair: | B5: Full area: LifeProof carpet & pad, concrete crack repair & leveling, drywall, wall paneling, all baseboard, texture, paint all walls
A6: Work Completed: | B6: Floor demo, mold treatment completed
A8: Category | B8: Material / Item | C8: Qty | D8: Unit | E8: Unit Cost | F8: Extended Cost | G8: Notes
A9: Flooring | B9: LifeProof w/ Petproof Technology - low pile carpet | C9: 61 | D9: SF | E9: =HYPERLINK("https://www.homedepot.com/b/Flooring-Carpet/Lifeproof-with-Petproof-Technology/N-5yc1vZarl0Zs7d",5.49) -> 5.49 | F9: =C9*E9 -> 334.89 | G9: Triexta, lifetime pet-stain warranty, 25yr wear
A10: Flooring | B10: LifeProof 1/2" Premium Comfort Foam pad (SpillSafe) | C10: 61 | D10: SF | E10: =HYPERLINK("https://www.homedepot.com/p/Lifeproof-1-2-in-Thick-Premium-Comfort-Foam-Carpet-Pad-with-Double-Sided-Waterproof-SpillSafe-Membrane-100502850-04/316061675",1.35) -> 1.35 | F10: =C10*E10 -> 82.35 | G10: Double-sided waterproof moisture barrier
A11: Flooring | B11: Tack strips | C11: 42 | D11: LF | E11: =HYPERLINK("https://www.homedepot.com/p/M-D-Building-Products-4-ft-Carpet-Tack-Strip-50-Pack-75093/202066639",0.45) -> 0.45 | F11: =C11*E11 -> 18.9 | G11: Full room perimeter
A12: Flooring | B12: Carpet seam tape | C12: 1 | D12: roll | E12: =HYPERLINK("https://www.homedepot.com/p/Roberts-3-in-x-164-ft-Hot-Melt-Seam-Tape-50-325/100147104",12.98) -> 12.98 | F12: =C12*E12 -> 12.98
A13: Concrete | B13: Epoxy crack filler (10oz cartridge) | C13: 2 | D13: ea | E13: =HYPERLINK("https://www.homedepot.com/p/DAP-Concrete-and-Mortar-Filler-and-Sealant-9-8-oz-Limestone-18096/202522393",9.98) -> 9.98 | F13: =C13*E13 -> 19.96 | G13: Phase 1: Individual crack repair
A14: Concrete | B14: Concrete crack backer rod (3/8") | C14: 1 | D14: roll | E14: =HYPERLINK("https://www.homedepot.com/p/M-D-Building-Products-3-8-in-x-20-ft-Caulk-Backer-Rod-71464/202066517",4.48) -> 4.48 | F14: =C14*E14 -> 4.48
A15: Concrete | B15: Concrete bonding adhesive | C15: 1 | D15: gal | E15: =HYPERLINK("https://www.homedepot.com/p/Quikrete-1-Qt-Concrete-Bonding-Adhesive-990201/100318507",9.98) -> 9.98 | F15: =C15*E15 -> 9.98
A16: Concrete | B16: Hydraulic cement (10 lb) | C16: 1 | D16: bag | E16: =HYPERLINK("https://www.homedepot.com/p/Quikrete-10-lb-Hydraulic-Water-Stop-Cement-112611/100318494",12.48) -> 12.48 | F16: =C16*E16 -> 12.48 | G16: Wider cracks / spalling
A17: Concrete | B17: Self-leveling compound (50 lb bag) | C17: 3 | D17: bag | E17: =HYPERLINK("https://www.homedepot.com/p/Henry-555-Level-Pro-40-lb-Self-Leveling-Underlayment-12165/100111942",36.97) -> 36.97 | F17: =C17*E17 -> 110.91 | G17: Phase 2 if needed: Full floor ~61 SF
A18: Concrete | B18: SLC primer / bonding agent (1 gal) | C18: 1 | D18: gal | E18: =HYPERLINK("https://www.homedepot.com/p/Henry-336-1-Gal-Floor-Primer-and-Underlayment-Additive-12195/100111940",27.98) -> 27.98 | F18: =C18*E18 -> 27.98 | G18: Required prep for SLC
A19: Drywall | B19: 1/2" x 4'x8' standard drywall | C19: 4 | D19: sheet | E19: =HYPERLINK("https://www.homedepot.com/p/USG-Sheetrock-Brand-1-2-in-x-4-ft-x-8-ft-UltraLight-Drywall-14113411708/202530243",11.98) -> 11.98 | F19: =C19*E19 -> 47.92
A20: Drywall | B20: Drywall screws 1-1/4" coarse (1 lb) | C20: 2 | D20: box | E20: =HYPERLINK("https://www.homedepot.com/p/Grip-Rite-6-x-1-1-4-in-Philips-Bugle-Head-Coarse-Thread-Sharp-Point-Drywall-Screws-1-lb-Pack-114CDWS1/100153837",8.47) -> 8.47 | F20: =C20*E20 -> 16.94
A21: Drywall | B21: Paper drywall tape (250 ft) | C21: 1 | D21: roll | E21: =HYPERLINK("https://www.homedepot.com/p/USG-Sheetrock-Brand-2-1-16-in-x-250-ft-Paper-Joint-Tape-382175/100321614",4.88) -> 4.88 | F21: =C21*E21 -> 4.88
A22: Drywall | B22: All-purpose joint compound (4.5 gal) | C22: 1 | D22: bucket | E22: =HYPERLINK("https://www.homedepot.com/p/USG-Sheetrock-Brand-4-5-Gal-All-Purpose-Pre-Mixed-Joint-Compound-380501/100321602",19.48) -> 19.48 | F22: =C22*E22 -> 19.48
A23: Drywall | B23: Lightweight finishing compound (4.5 gal) | C23: 1 | D23: bucket | E23: =HYPERLINK("https://www.homedepot.com/p/USG-Sheetrock-Brand-4-5-Gal-Plus-3-Lightweight-All-Purpose-Pre-Mixed-Joint-Compound-381466/100321604",20.98) -> 20.98 | F23: =C23*E23 -> 20.98
A24: Drywall | B24: Sanding sponge (med/fine) | C24: 3 | D24: ea | E24: =HYPERLINK("https://www.homedepot.com/p/3M-2-7-8-in-x-4-7-8-in-x-1-in-Fine-Medium-Drywall-Sanding-Sponge-9093DCNA/100353968",4.97) -> 4.97 | F24: =C24*E24 -> 14.91
A25: Walls | B25: Wall paneling - 4'x8' sheets (match existing) | C25: 4 | D25: sheet | E25: =HYPERLINK("https://www.homedepot.com/p/1-4-in-x-48-in-x-96-in-DPI-Pinetex-White-Wainscot-Panel-173/100029362",34.98) -> 34.98 | F25: =C25*E25 -> 139.92
A26: Walls | B26: Panel adhesive (heavy duty) | C26: 3 | D26: tube | E26: =HYPERLINK("https://www.homedepot.com/p/Loctite-Power-Grab-Express-9-fl-oz-All-Purpose-Construction-Adhesive-2029846/206736498",7.98) -> 7.98 | F26: =C26*E26 -> 23.94
A27: Walls | B27: Paneling trim / seam molding (8ft) | C27: 4 | D27: piece | E27: =HYPERLINK("https://www.homedepot.com/p/Woodgrain-Millwork-WM-135-3-32-in-x-1-5-8-in-x-84-in-Primed-Finger-Jointed-Batten-Moulding-10001854/206082010",4.98) -> 4.98 | F27: =C27*E27 -> 19.92
A28: Walls | B28: Panel nails (color-matched) | C28: 1 | D28: box | E28: =HYPERLINK("https://www.homedepot.com/p/Grip-Rite-1-in-Panel-Board-Nails-1-lb-Pack-1PNBR1/100120289",6.98) -> 6.98 | F28: =C28*E28 -> 6.98
A29: Trim | B29: Baseboard - 3-1/4" MDF primed (8ft) | C29: 6 | D29: piece | E29: =HYPERLINK("https://www.homedepot.com/p/Woodgrain-Millwork-623-1-2-in-x-3-1-4-in-x-96-in-Primed-MDF-Baseboard-Moulding-1-Piece-8-Total-Linear-Feet-10001007/203209370",8.98) -> 8.98 | F29: =C29*E29 -> 53.88 | G29: ~42 LF full perimeter
A30: Trim | B30: Inside/outside corner blocks | C30: 6 | D30: ea | E30: =HYPERLINK("https://www.homedepot.com/p/House-of-Fara-3-4-in-x-3-1-4-in-x-3-1-4-in-MDF-Primed-Plinth-Block-8621/205426918",3.98) -> 3.98 | F30: =C30*E30 -> 23.88
A31: Trim | B31: 18ga 2" brad nails (1000ct) | C31: 1 | D31: box | E31: =HYPERLINK("https://www.homedepot.com/p/Grip-Rite-2-in-18-Gauge-Brad-Nails-1000-Pack-GRF18200/202308594",7.98) -> 7.98 | F31: =C31*E31 -> 7.98
A32: Trim | B32: Paintable latex caulk | C32: 2 | D32: tube | E32: =HYPERLINK("https://www.homedepot.com/p/DAP-Alex-Plus-10-1-oz-White-Acrylic-Latex-Caulk-Plus-Silicone-18103/100097524",3.98) -> 3.98 | F32: =C32*E32 -> 7.96
A33: Trim | B33: Wood filler / spackle | C33: 1 | D33: tube | E33: =HYPERLINK("https://www.homedepot.com/p/DAP-Plastic-Wood-X-with-DryDex-5-5-oz-All-Purpose-Wood-Filler-00540/206667344",6.98) -> 6.98 | F33: =C33*E33 -> 6.98
A34: Texture | B34: Spray texture - orange peel/knockdown (25oz) | C34: 3 | D34: can | E34: =HYPERLINK("https://www.homedepot.com/p/Homax-20-oz-Wall-Orange-Peel-Low-Odor-Water-Based-Texture-Spray-Paint-4092-06/100154309",16.98) -> 16.98 | F34: =C34*E34 -> 50.94 | G34: Match existing
A35: Paint | B35: Zinsser Bulls Eye 1-2-3 Primer (1 gal) | C35: 1 | D35: gal | E35: =HYPERLINK("https://www.homedepot.com/p/Zinsser-Bulls-Eye-1-2-3-1-Gal-White-Water-Based-Interior-Exterior-Primer-and-Sealer-2001/100398391",28.98) -> 28.98 | F35: =C35*E35 -> 28.98
A36: Paint | B36: BEHR Marquee interior paint - eggshell (1 gal) | C36: 2 | D36: gal | E36: =HYPERLINK("https://www.homedepot.com/p/BEHR-MARQUEE-1-gal-Ultra-Pure-White-Eggshell-Enamel-Interior-Paint-Primer-245001/204747490",54.98) -> 54.98 | F36: =C36*E36 -> 109.96
A37: Paint | B37: BEHR Marquee semi-gloss trim paint (1 qt) | C37: 1 | D37: qt | E37: =HYPERLINK("https://www.homedepot.com/p/BEHR-MARQUEE-1-qt-Ultra-Pure-White-Semi-Gloss-Enamel-Interior-Paint-Primer-345004/204747525",23.98) -> 23.98 | F37: =C37*E37 -> 23.98
A38: Paint | B38: Paint supplies | C38: 1 | D38: kit | E38: =HYPERLINK("https://www.homedepot.com/p/Wooster-9-in-x-3-8-in-Pro-American-Contractor-High-Density-Knit-Roller-Cover-3-Pack-0-RC660-9/205625717",11.97) -> 11.97 | F38: =C38*E38 -> 11.97
A39: Supplies | B39: Plastic sheeting / drop cloths | C39: 1 | D39: pack | E39: =HYPERLINK("https://www.homedepot.com/p/HDX-9-ft-x-12-ft-0-7-mil-Drop-Cloth-2-Pack-DCHD-07-2/202528629",6.98) -> 6.98 | F39: =C39*E39 -> 6.98
A40: Supplies | B40: Disposal / debris hauling | C40: 1 | D40: flat | E40: 60 | F40: =C40*E40 -> 60 | G40: Old materials removal
A41: >>> OWNER-PERFORMED LABOR (valued at contractor equivalent rates)
A42: Owner Labor | B42: Carpet & pad removal (old) | C42: 61 | D42: SF | E42: 0.85 | F42: =C42*E42 -> 51.85 | G42: See Pricing Sources tab
...

Sheet Pricing Sources
A1: Pricing Sources & Methodology
A3: MATERIAL PRICING: All material unit costs link directly to the product or search results page at the retailer. Click the blue underlined unit cost in any room tab to view the source. Prices based on Home Depot and manufacturer websites as of April 2026.
A5: Labor Category | B5: Rate | C5: Source | D5: Date Accessed
A6: Carpet removal | B6: $0.85/SF | C6: =HYPERLINK("https://homeguide.com/costs/carpet-installation-cost","HomeGuide - Carpet Installation Cost Guide") -> HomeGuide - Carpet Installation Cost Guide | D6: April 2026
A7: Carpet installation (professional) | B7: $2.00/SF | C7: =HYPERLINK("https://homeguide.com/costs/carpet-installation-cost","HomeGuide - Carpet Installation Cost (2026)") -> HomeGuide - Carpet Installation Cost (2026) | D7: April 2026
A8: Drywall hang, tape, mud, sand | B8: $2.75/SF | C8: =HYPERLINK("https://homeguide.com/costs/sheetrock-drywall-prices","HomeGuide - Drywall Prices Chart (2026)") -> HomeGuide - Drywall Prices Chart (2026) | D8: April 2026
A9: Texture application | B9: $1.50/SF | C9: =HYPERLINK("https://homeguide.com/costs/sheetrock-drywall-prices","HomeGuide - Drywall Prices Chart (2026)") -> HomeGuide - Drywall Prices Chart (2026) | D9: April 2026
A10: Baseboard removal | B10: $1.25/LF | C10: =HYPERLINK("https://www.angi.com/articles/how-much-does-it-cost-replace-baseboards.htm","Angi - Baseboard Installation Cost (2026)") -> Angi - Baseboard Installation Cost (2026) | D10: April 2026
A11: Baseboard installation | B11: $7.00-8.25/LF | C11: =HYPERLINK("https://homeguide.com/costs/baseboard-installation-cost","HomeGuide - Baseboard Installation Cost (2026)") -> HomeGuide - Baseboard Installation Cost (2026) | D11: April 2026
A12: Painting walls (prime + 2 coats) | B12: $1.75-2.00/SF | C12: =HYPERLINK("https://homeguide.com/costs/interior-painting-cost","HomeGuide - Interior Painting Cost") -> HomeGuide - Interior Painting Cost | D12: April 2026
A13: LVP flooring installation | B13: $3.00/SF | C13: =HYPERLINK("https://homeguide.com/costs/vinyl-flooring-installation-cost","HomeGuide - Vinyl Flooring Installation Cost") -> HomeGuide - Vinyl Flooring Installation Cost | D13: April 2026
A14: Vinyl floor installation | B14: $3.50/SF | C14: =HYPERLINK("https://homeguide.com/costs/vinyl-flooring-installation-cost","HomeGuide - Vinyl Flooring Installation Cost") -> HomeGuide - Vinyl Flooring Installation Cost | D14: April 2026
A15: Door & trim installation | B15: $325/ea | C15: =HYPERLINK("https://www.angi.com/articles/how-much-does-installing-trim-cost.htm","Angi - Trim Installation Cost (2026)") -> Angi - Trim Installation Cost (2026) | D15: April 2026
A16: Tile surround installation | B16: $10.00/SF | C16: =HYPERLINK("https://homeguide.com/costs/tile-installation-cost","HomeGuide - Tile Installation Cost (2026)") -> HomeGuide - Tile Installation Cost (2026) | D16: April 2026
A17: Vanity set & plumbing hookup | B17: $250/ea | C17: =HYPERLINK("https://www.angi.com/articles/how-much-does-vanity-installation-cost.htm","Angi - Vanity Installation Cost") -> Angi - Vanity Installation Cost | D17: April 2026
A18: Drywall skim coat | B18: $1.75/SF | C18: =HYPERLINK("https://homeguide.com/costs/sheetrock-drywall-prices","HomeGuide - Drywall Prices Chart") -> HomeGuide - Drywall Prices Chart | D18: April 2026
A19: Wall paneling installation | B19: $2.25/SF | C19: =HYPERLINK("https://homeguide.com/costs/paneling-installation-cost","HomeGuide - Paneling Installation Cost") -> HomeGuide - Paneling Installation Cost | D19: April 2026
A20: Concrete crack repair | B20: $8.00/LF | C20: =HYPERLINK("https://www.homewyse.com/maintenance_costs/cost_to_repair_cracked_concrete.html","Homewyse - Concrete Crack Repair (2026)") -> Homewyse - Concrete Crack Repair (2026) | D20: April 2026
A21: Concrete self-leveling | B21: $3.50/SF | C21: =HYPERLINK("https://homeguide.com/costs/concrete-leveling-cost","HomeGuide - Concrete Leveling Cost (2026)") -> HomeGuide - Concrete Leveling Cost (2026) | D21: April 2026
A22: DreamStone shower system installation | B22: $800/ea | C22: =HYPERLINK("https://dreamline.com/shower-kits/dreamstone","DreamLine DreamStone - manufacturer site") -> DreamLine DreamStone - manufacturer site | D22: April 2026
A24: Note: Owner-performed labor is valued at the same rates a licensed contractor would charge. This reflects the fair market value of the work regardless of who performs it. Rates are based on 2025-2026 national averages from the sources listed above. Roanoke, VA market rates may vary slightly.
